{"schemaVersion":{"major":0,"patch":0,"minor":3},"primaryContentSections":[{"declarations":[{"platforms":["macOS"],"tokens":[{"text":"static","kind":"keyword"},{"kind":"text","text":" "},{"kind":"keyword","text":"func"},{"text":" ","kind":"text"},{"text":"withMappedExceptions","kind":"identifier"},{"text":"<","kind":"text"},{"text":"T","kind":"genericParameter"},{"text":">(","kind":"text"},{"text":"_","kind":"externalParam"},{"kind":"text","text":" "},{"kind":"internalParam","text":"customError"},{"kind":"text","text":": (any "},{"kind":"typeIdentifier","preciseIdentifier":"s:s5ErrorP","text":"Error"},{"text":")? = nil, ","kind":"text"},{"text":"_","kind":"externalParam"},{"kind":"text","text":" "},{"text":"function","kind":"internalParam"},{"kind":"text","text":": () "},{"text":"async","kind":"keyword"},{"text":" ","kind":"text"},{"kind":"keyword","text":"throws"},{"kind":"text","text":" -> "},{"kind":"typeIdentifier","identifier":"doc:\/\/NodeKit\/documentation\/NodeKit\/NodeResult","text":"NodeResult","preciseIdentifier":"s:7NodeKit0A6Resulta"},{"kind":"text","text":"<"},{"kind":"typeIdentifier","text":"T"},{"kind":"text","text":">) "},{"kind":"keyword","text":"async"},{"text":" -> ","kind":"text"},{"identifier":"doc:\/\/NodeKit\/documentation\/NodeKit\/NodeResult","text":"NodeResult","preciseIdentifier":"s:7NodeKit0A6Resulta","kind":"typeIdentifier"},{"kind":"text","text":"<"},{"kind":"typeIdentifier","text":"T"},{"text":">","kind":"text"}],"languages":["swift"]}],"kind":"declarations"},{"parameters":[{"content":[{"inlineContent":[{"text":"The error that will be passed to failure instead of the Exception","type":"text"}],"type":"paragraph"}],"name":"customError"},{"content":[{"inlineContent":[{"text":"Asynchronous function that can throw an Exception","type":"text"}],"type":"paragraph"}],"name":"function"}],"kind":"parameters"},{"kind":"content","content":[{"anchor":"return-value","type":"heading","text":"Return Value","level":2},{"inlineContent":[{"text":"The result with transformed Exceptions into failure.","type":"text"}],"type":"paragraph"}]}],"kind":"symbol","hierarchy":{"paths":[["doc:\/\/NodeKit\/documentation\/NodeKit","doc:\/\/NodeKit\/documentation\/NodeKit\/Swift","doc:\/\/NodeKit\/documentation\/NodeKit\/Swift\/Result"]]},"metadata":{"role":"symbol","symbolKind":"method","roleHeading":"Type Method","conformance":{"constraints":[{"code":"Failure","type":"codeVoice"},{"text":" conforms to ","type":"text"},{"type":"codeVoice","code":"Error"},{"type":"text","text":"."}],"availabilityPrefix":[{"text":"Available when","type":"text"}],"conformancePrefix":[{"type":"text","text":"Conforms when"}]},"title":"withMappedExceptions(_:_:)","modules":[{"relatedModules":["Swift"],"name":"NodeKit"}],"fragments":[{"text":"static","kind":"keyword"},{"text":" ","kind":"text"},{"text":"func","kind":"keyword"},{"text":" ","kind":"text"},{"kind":"identifier","text":"withMappedExceptions"},{"kind":"text","text":"<"},{"kind":"genericParameter","text":"T"},{"text":">((any ","kind":"text"},{"kind":"typeIdentifier","preciseIdentifier":"s:s5ErrorP","text":"Error"},{"kind":"text","text":")?, () "},{"text":"async","kind":"keyword"},{"text":" ","kind":"text"},{"kind":"keyword","text":"throws"},{"text":" -> ","kind":"text"},{"text":"NodeResult","preciseIdentifier":"s:7NodeKit0A6Resulta","kind":"typeIdentifier"},{"text":"<","kind":"text"},{"text":"T","kind":"typeIdentifier"},{"kind":"text","text":">) "},{"text":"async","kind":"keyword"},{"text":" -> ","kind":"text"},{"text":"NodeResult","preciseIdentifier":"s:7NodeKit0A6Resulta","kind":"typeIdentifier"},{"kind":"text","text":"<"},{"text":"T","kind":"typeIdentifier"},{"text":">","kind":"text"}],"extendedModule":"Swift","externalID":"s:s6ResultO7NodeKitE20withMappedExceptionsyAByqd__s5Error_pGsAE_pSg_AFyYaKXEtYalFZ"},"identifier":{"url":"doc:\/\/NodeKit\/documentation\/NodeKit\/Swift\/Result\/withMappedExceptions(_:_:)","interfaceLanguage":"swift"},"sections":[],"abstract":[{"type":"text","text":"Method that calls an asynchronous function and wraps caught Exceptions in a failure(error)"}],"variants":[{"traits":[{"interfaceLanguage":"swift"}],"paths":["\/documentation\/nodekit\/swift\/result\/withmappedexceptions(_:_:)"]}],"references":{"doc://NodeKit/documentation/NodeKit":{"role":"collection","type":"topic","identifier":"doc:\/\/NodeKit\/documentation\/NodeKit","kind":"symbol","title":"NodeKit","url":"\/documentation\/nodekit","abstract":[]},"doc://NodeKit/documentation/NodeKit/Swift":{"abstract":[],"title":"Swift","identifier":"doc:\/\/NodeKit\/documentation\/NodeKit\/Swift","role":"collection","type":"topic","kind":"symbol","url":"\/documentation\/nodekit\/swift"},"doc://NodeKit/documentation/NodeKit/NodeResult":{"type":"topic","navigatorTitle":[{"text":"NodeResult","kind":"identifier"}],"identifier":"doc:\/\/NodeKit\/documentation\/NodeKit\/NodeResult","title":"NodeResult","abstract":[{"text":"Result of the nodeâ€™s data processing method.","type":"text"}],"url":"\/documentation\/nodekit\/noderesult","kind":"symbol","role":"symbol","fragments":[{"kind":"keyword","text":"typealias"},{"text":" ","kind":"text"},{"text":"NodeResult","kind":"identifier"}]},"doc://NodeKit/documentation/NodeKit/Swift/Result/withMappedExceptions(_:_:)":{"conformance":{"availabilityPrefix":[{"type":"text","text":"Available when"}],"constraints":[{"code":"Failure","type":"codeVoice"},{"type":"text","text":" conforms to "},{"code":"Error","type":"codeVoice"},{"text":".","type":"text"}],"conformancePrefix":[{"text":"Conforms when","type":"text"}]},"role":"symbol","title":"withMappedExceptions(_:_:)","abstract":[{"text":"Method that calls an asynchronous function and wraps caught Exceptions in a failure(error)","type":"text"}],"identifier":"doc:\/\/NodeKit\/documentation\/NodeKit\/Swift\/Result\/withMappedExceptions(_:_:)","type":"topic","kind":"symbol","fragments":[{"kind":"keyword","text":"static"},{"kind":"text","text":" "},{"kind":"keyword","text":"func"},{"kind":"text","text":" "},{"text":"withMappedExceptions","kind":"identifier"},{"kind":"text","text":"<"},{"kind":"genericParameter","text":"T"},{"kind":"text","text":">((any "},{"text":"Error","preciseIdentifier":"s:s5ErrorP","kind":"typeIdentifier"},{"text":")?, () ","kind":"text"},{"text":"async","kind":"keyword"},{"kind":"text","text":" "},{"kind":"keyword","text":"throws"},{"text":" -> ","kind":"text"},{"text":"NodeResult","kind":"typeIdentifier","preciseIdentifier":"s:7NodeKit0A6Resulta"},{"text":"<","kind":"text"},{"kind":"typeIdentifier","text":"T"},{"text":">) ","kind":"text"},{"kind":"keyword","text":"async"},{"kind":"text","text":" -> "},{"text":"NodeResult","preciseIdentifier":"s:7NodeKit0A6Resulta","kind":"typeIdentifier"},{"kind":"text","text":"<"},{"text":"T","kind":"typeIdentifier"},{"text":">","kind":"text"}],"url":"\/documentation\/nodekit\/swift\/result\/withmappedexceptions(_:_:)"},"doc://NodeKit/documentation/NodeKit/Swift/Result":{"identifier":"doc:\/\/NodeKit\/documentation\/NodeKit\/Swift\/Result","navigatorTitle":[{"text":"Result","kind":"identifier"}],"url":"\/documentation\/nodekit\/swift\/result","title":"Result","role":"symbol","fragments":[{"kind":"keyword","text":"extension"},{"kind":"text","text":" "},{"preciseIdentifier":"s:s6ResultO","kind":"identifier","text":"Result"}],"abstract":[],"type":"topic","kind":"symbol"}}}